<mujoco model="fr5_gripper">
  <option timestep="0.002" gravity="0 0 -9.81" integrator="implicitfast" />
  <compiler angle="radian" />
  <default>
    <default class="2f85">
      <mesh scale="0.001 0.001 0.001" />
      <general biastype="affine" />
      <joint axis="0 0 1" />
      <default class="driver">
        <joint range="0 0.9" armature="0.005" damping="0.1" solimplimit="0.95 0.99 0.001" solreflimit="0.005 1" />
      </default>
      <default class="follower">
        <joint range="-0.872664 0.9" armature="0.001" solimplimit="0.95 0.99 0.001" solreflimit="0.005 1" />
      </default>
      <default class="spring_link">
        <joint range="-0.29670597283 0.9" armature="0.001" stiffness="0.05" springref="2.62" damping="0.00125" />
      </default>
      <default class="coupler">
        <joint range="-1.57 0" armature="0.001" solimplimit="0.95 0.99 0.001" solreflimit="0.005 1" />
      </default>
      <default class="visual_gripper">
        <geom type="mesh" contype="0" conaffinity="0" group="2" material="black" />
      </default>
      <default class="collision_gripper">
        <geom group="3" type="mesh" contype="0" conaffinity="0" />
        <default class="pad_box1">
          <geom group="3" mass="1e-6" type="box" pos="0.043258 0 0.12" size="0.002 0.011 0.009375" solimp="0.99 0.995 0.01" solref="0.01 1" friction="1 0.005 0.0001" rgba="1.0 0.55 0.55 1" conaffinity="3" />
        </default>
        <default class="pad_box2">
          <geom group="3" mass="1e-6" type="box" pos="0.041258 0 0.12875" size="0.004 0.011 0.01875" solimp="0.99 0.995 0.01" solref="0.01 1" friction="1 0.005 0.0001" rgba="0.0 0.45 0.45 1" conaffinity="3" />
        </default>
      </default>
    </default>
  </default>
  <asset>
    <material name="black" rgba="0.25 0.25 0.25 1" />
    <material name="metal" rgba="0.58 0.58 0.58 1" />
    <material name="table_top_light" rgba="0.95 0.87 0.75 1" specular="0.9" shininess="0.85" reflectance="0.32" />
    <material name="table_top_mid" rgba="0.36 0.38 0.40 1" specular="0.75" shininess="0.65" reflectance="0.22" />
    <material name="table_groove_dark" rgba="0.45 0.45 0.40 1" specular="0.45" shininess="0.35" reflectance="0.12" />
    <material name="frame_black" rgba="0.39 0.35 0.34 1" specular="0.15" shininess="0.05" />
    <material name="black_tape" rgba="0.005 0.005 0.005 1" specular="0.05" shininess="0.02" reflectance="0.0" />
    <material name="fr5_white" rgba="0.60 0.59 0.59 1" />
    <material name="fr5_shadow_white" rgba="0.72 0.72 0.68 1" />
    <material name="red_tape" rgba="0.95 0.78 0.08 1" specular="0.75" shininess="0.65" reflectance="0.18" />
    <material name="yellow_tape" rgba="0.74 0.31 0.29 1" specular="0.75" shininess="0.65" reflectance="0.18" />
    <material name="white_tape_roll" rgba="0.92 0.88 0.80 1" specular="0.55" shininess="0.40" reflectance="0.12" />
    <material name="white_tape_hub" rgba="0.85 0.78 0.70 1" specular="0.08" shininess="0.03" />
    <material name="myd_part_gray" rgba="0.1 0.1 0.1 1" specular="0.35" shininess="0.25" />
    <mesh name="base_link" content_type="model/stl" file="meshes/fairino5_v6/base_link.STL" />
    <mesh name="shoulder_link" content_type="model/stl" file="meshes/fairino5_v6/shoulder_link.STL" />
    <mesh name="upperarm_link" content_type="model/stl" file="meshes/fairino5_v6/upperarm_link.STL" />
    <mesh name="forearm_link" content_type="model/stl" file="meshes/fairino5_v6/forearm_link.STL" />
    <mesh name="wrist1_link" content_type="model/stl" file="meshes/fairino5_v6/wrist1_link.STL" />
    <mesh name="wrist2_link" content_type="model/stl" file="meshes/fairino5_v6/wrist2_link.STL" />
    <mesh name="wrist3_link" content_type="model/stl" file="meshes/fairino5_v6/wrist3_link.STL" />
    <mesh name="robotiq_base" file="meshes/robotiq/base.stl" />
    <mesh name="base_coupling" file="meshes/robotiq/base_coupling.stl" />
    <mesh name="c-a01-85-open" file="meshes/robotiq/c-a01-85-open.stl" />
    <mesh name="driver" file="meshes/robotiq/driver.stl" />
    <mesh name="coupler" file="meshes/robotiq/coupler.stl" />
    <mesh name="spring_link" file="meshes/robotiq/spring_link.stl" />
    <mesh name="follower" file="meshes/robotiq/follower.stl" />
    <mesh name="tongue" file="meshes/robotiq/tongue.stl" />
    <mesh name="red_tape_roll_red" file="meshes/objects/red_tape_roll_red.obj" />
    <mesh name="red_tape_roll_white_hub" file="meshes/objects/red_tape_roll_white_hub.obj" />
    <mesh name="myd_part1" file="meshes/objects/myd_part1.stl" scale="0.001 0.001 0.001" />
  </asset>
  <worldbody>
    <light name="room_light_center"
       pos="-0.485 -0.26 3.0"
       dir="0 0 -1"
       diffuse="0.42 0.42 0.42"
       ambient="0.28 0.28 0.28"
       specular="0.10 0.10 0.10"
       directional="false"
       castshadow="true"/>
    <light name="room_light_corner_xp_yp"
       pos="-0.085 0.14 3.0"
       dir="0 0 -1"
       diffuse="0.16 0.16 0.16"
       ambient="0.02 0.02 0.02"
       specular="0.04 0.04 0.04"
       directional="false"
       castshadow="true"/>
    <light name="room_light_corner_xp_yn"
       pos="-0.085 -0.66 3.0"
       dir="0 0 -1"
       diffuse="0.16 0.16 0.16"
       ambient="0.02 0.02 0.02"
       specular="0.04 0.04 0.04"
       directional="false"
       castshadow="true"/>
    <light name="room_light_corner_xn_yp"
       pos="-0.885 0.14 3.0"
       dir="0 0 -1"
       diffuse="0.16 0.16 0.16"
       ambient="0.02 0.02 0.02"
       specular="0.04 0.04 0.04"
       directional="false"
       castshadow="true"/>
    <light name="room_light_corner_xn_yn"
       pos="-0.885 -0.66 3.0"
       dir="0 0 -1"
       diffuse="0.16 0.16 0.16"
       ambient="0.02 0.02 0.02"
       specular="0.04 0.04 0.04"
       directional="false"
       castshadow="true"/>
    <body name="grooved_table">
      <geom name="grooved_table_base" type="box" pos="-0.485 -0.26 -0.0265" size="0.75 0.5 0.0235" material="table_top_mid" />
      <geom name="grooved_table_flat_00" type="box" pos="-0.485 -0.7525 -0.0015" size="0.75 0.0075 0.0015" material="table_top_light" />
      <geom name="grooved_table_flat_01" type="box" pos="-0.485 -0.7275 -0.0015" size="0.75 0.0075 0.0015" material="table_top_light" />
      <geom name="grooved_table_flat_02" type="box" pos="-0.485 -0.7125 -0.0015" size="0.75 0.0075 0.0015" material="table_top_light" />
      <geom name="grooved_table_flat_03" type="box" pos="-0.485 -0.6875 -0.0015" size="0.75 0.0075 0.0015" material="table_top_light" />
      <geom name="grooved_table_flat_04" type="box" pos="-0.485 -0.6725 -0.0015" size="0.75 0.0075 0.0015" material="table_top_light" />
      <geom name="grooved_table_flat_05" type="box" pos="-0.485 -0.6475 -0.0015" size="0.75 0.0075 0.0015" material="table_top_light" />
      <geom name="grooved_table_flat_06" type="box" pos="-0.485 -0.6325 -0.0015" size="0.75 0.0075 0.0015" material="table_top_light" />
      <geom name="grooved_table_flat_07" type="box" pos="-0.485 -0.6075 -0.0015" size="0.75 0.0075 0.0015" material="table_top_light" />
      <geom name="grooved_table_flat_08" type="box" pos="-0.485 -0.5925 -0.0015" size="0.75 0.0075 0.0015" material="table_top_light" />
      <geom name="grooved_table_flat_09" type="box" pos="-0.485 -0.5675 -0.0015" size="0.75 0.0075 0.0015" material="table_top_light" />
      <geom name="grooved_table_flat_10" type="box" pos="-0.485 -0.5525 -0.0015" size="0.75 0.0075 0.0015" material="table_top_light" />
      <geom name="grooved_table_flat_11" type="box" pos="-0.485 -0.5275 -0.0015" size="0.75 0.0075 0.0015" material="table_top_light" />
      <geom name="grooved_table_flat_12" type="box" pos="-0.485 -0.5125 -0.0015" size="0.75 0.0075 0.0015" material="table_top_light" />
      <geom name="grooved_table_flat_13" type="box" pos="-0.485 -0.4875 -0.0015" size="0.75 0.0075 0.0015" material="table_top_light" />
      <geom name="grooved_table_flat_14" type="box" pos="-0.485 -0.4725 -0.0015" size="0.75 0.0075 0.0015" material="table_top_light" />
      <geom name="grooved_table_flat_15" type="box" pos="-0.485 -0.4475 -0.0015" size="0.75 0.0075 0.0015" material="table_top_light" />
      <geom name="grooved_table_flat_16" type="box" pos="-0.485 -0.4325 -0.0015" size="0.75 0.0075 0.0015" material="table_top_light" />
      <geom name="grooved_table_flat_17" type="box" pos="-0.485 -0.4075 -0.0015" size="0.75 0.0075 0.0015" material="table_top_light" />
      <geom name="grooved_table_flat_18" type="box" pos="-0.485 -0.3925 -0.0015" size="0.75 0.0075 0.0015" material="table_top_light" />
      <geom name="grooved_table_flat_19" type="box" pos="-0.485 -0.3675 -0.0015" size="0.75 0.0075 0.0015" material="table_top_light" />
      <geom name="grooved_table_flat_20" type="box" pos="-0.485 -0.3525 -0.0015" size="0.75 0.0075 0.0015" material="table_top_light" />
      <geom name="grooved_table_flat_21" type="box" pos="-0.485 -0.3275 -0.0015" size="0.75 0.0075 0.0015" material="table_top_light" />
      <geom name="grooved_table_flat_22" type="box" pos="-0.485 -0.3125 -0.0015" size="0.75 0.0075 0.0015" material="table_top_light" />
      <geom name="grooved_table_flat_23" type="box" pos="-0.485 -0.2875 -0.0015" size="0.75 0.0075 0.0015" material="table_top_light" />
      <geom name="grooved_table_flat_24" type="box" pos="-0.485 -0.2725 -0.0015" size="0.75 0.0075 0.0015" material="table_top_light" />
      <geom name="grooved_table_flat_25" type="box" pos="-0.485 -0.2475 -0.0015" size="0.75 0.0075 0.0015" material="table_top_light" />
      <geom name="grooved_table_flat_26" type="box" pos="-0.485 -0.2325 -0.0015" size="0.75 0.0075 0.0015" material="table_top_light" />
      <geom name="grooved_table_flat_27" type="box" pos="-0.485 -0.2075 -0.0015" size="0.75 0.0075 0.0015" material="table_top_light" />
      <geom name="grooved_table_flat_28" type="box" pos="-0.485 -0.1925 -0.0015" size="0.75 0.0075 0.0015" material="table_top_light" />
      <geom name="grooved_table_flat_29" type="box" pos="-0.485 -0.1675 -0.0015" size="0.75 0.0075 0.0015" material="table_top_light" />
      <geom name="grooved_table_flat_30" type="box" pos="-0.485 -0.1525 -0.0015" size="0.75 0.0075 0.0015" material="table_top_light" />
      <geom name="grooved_table_flat_31" type="box" pos="-0.485 -0.1275 -0.0015" size="0.75 0.0075 0.0015" material="table_top_light" />
      <geom name="grooved_table_flat_32" type="box" pos="-0.485 -0.1125 -0.0015" size="0.75 0.0075 0.0015" material="table_top_light" />
      <geom name="grooved_table_flat_33" type="box" pos="-0.485 -0.0875 -0.0015" size="0.75 0.0075 0.0015" material="table_top_light" />
      <geom name="grooved_table_flat_34" type="box" pos="-0.485 -0.0725 -0.0015" size="0.75 0.0075 0.0015" material="table_top_light" />
      <geom name="grooved_table_flat_35" type="box" pos="-0.485 -0.0475 -0.0015" size="0.75 0.0075 0.0015" material="table_top_light" />
      <geom name="grooved_table_flat_36" type="box" pos="-0.485 -0.0325 -0.0015" size="0.75 0.0075 0.0015" material="table_top_light" />
      <geom name="grooved_table_flat_37" type="box" pos="-0.485 -0.0075 -0.0015" size="0.75 0.0075 0.0015" material="table_top_light" />
      <geom name="grooved_table_flat_38" type="box" pos="-0.485 0.0075 -0.0015" size="0.75 0.0075 0.0015" material="table_top_light" />
      <geom name="grooved_table_flat_39" type="box" pos="-0.485 0.0325 -0.0015" size="0.75 0.0075 0.0015" material="table_top_light" />
      <geom name="grooved_table_flat_40" type="box" pos="-0.485 0.0475 -0.0015" size="0.75 0.0075 0.0015" material="table_top_light" />
      <geom name="grooved_table_flat_41" type="box" pos="-0.485 0.0725 -0.0015" size="0.75 0.0075 0.0015" material="table_top_light" />
      <geom name="grooved_table_flat_42" type="box" pos="-0.485 0.0875 -0.0015" size="0.75 0.0075 0.0015" material="table_top_light" />
      <geom name="grooved_table_flat_43" type="box" pos="-0.485 0.1125 -0.0015" size="0.75 0.0075 0.0015" material="table_top_light" />
      <geom name="grooved_table_flat_44" type="box" pos="-0.485 0.1275 -0.0015" size="0.75 0.0075 0.0015" material="table_top_light" />
      <geom name="grooved_table_flat_45" type="box" pos="-0.485 0.1525 -0.0015" size="0.75 0.0075 0.0015" material="table_top_light" />
      <geom name="grooved_table_flat_46" type="box" pos="-0.485 0.1675 -0.0015" size="0.75 0.0075 0.0015" material="table_top_light" />
      <geom name="grooved_table_flat_47" type="box" pos="-0.485 0.1925 -0.0015" size="0.75 0.0075 0.0015" material="table_top_light" />
      <geom name="grooved_table_flat_48" type="box" pos="-0.485 0.2075 -0.0015" size="0.75 0.0075 0.0015" material="table_top_light" />
      <geom name="grooved_table_flat_49" type="box" pos="-0.485 0.2325 -0.0015" size="0.75 0.0075 0.0015" material="table_top_light" />
      <geom name="black_tape_frame_left_mid_back" type="box" pos="-0.755 -0.2370 0.0012" size="0.12 0.02 0.0012" material="black_tape" contype="0" conaffinity="0" group="2" />
      <geom name="black_tape_frame_left_mid_front" type="box" pos="-0.755 -0.0870 0.0012" size="0.12 0.02 0.0012" material="black_tape" contype="0" conaffinity="0" group="2" />
      <geom name="black_tape_frame_left_mid_left" type="box" pos="-0.855 -0.165 0.0012" size="0.02 0.075 0.0012" material="black_tape" contype="0" conaffinity="0" group="2" />
      <geom name="black_tape_frame_left_mid_right" type="box" pos="-0.655 -0.165 0.0012" size="0.02 0.075 0.0012" material="black_tape" contype="0" conaffinity="0" group="2" />
      
      <geom name="black_tape_frame_left_front_back" type="box" pos="-0.7625 -0.002 0.0012" size="0.1125 0.02 0.0012" material="black_tape" contype="0" conaffinity="0" group="2" />
      <geom name="black_tape_frame_left_front_front" type="box" pos="-0.7625 0.143 0.0012" size="0.1125 0.02 0.0012" material="black_tape" contype="0" conaffinity="0" group="2" />
      <geom name="black_tape_frame_left_front_left" type="box" pos="-0.855 0.07 0.0012" size="0.02 0.07250 0.0012" material="black_tape" contype="0" conaffinity="0" group="2" />
      <geom name="black_tape_frame_left_front_right" type="box" pos="-0.67 0.07 0.0012" size="0.02 0.07250 0.0012" material="black_tape" contype="0" conaffinity="0" group="2" />
      
      <geom name="black_tape_frame_center_front_back" type="box" pos="-0.44 -0.0420 0.0012" size="0.120 0.02 0.0012" material="black_tape" contype="0" conaffinity="0" group="2" />
      <geom name="black_tape_frame_center_front_front" type="box" pos="-0.44 0.1430 0.0012" size="0.120 0.02 0.0012" material="black_tape" contype="0" conaffinity="0" group="2" />
      <geom name="black_tape_frame_center_front_left" type="box" pos="-0.34 0.046 0.0012" size="0.02 0.0850 0.0012" material="black_tape" contype="0" conaffinity="0" group="2" />
      <geom name="black_tape_frame_center_front_right" type="box" pos="-0.54 0.046 0.0012" size="0.02 0.0850 0.0012" material="black_tape" contype="0" conaffinity="0" group="2" />
    </body>
    <body name="red_tape_roll" pos="-0.44 0.046 0.0215">
      <freejoint name="red_tape_roll_joint" />
      <geom name="red_tape_roll_red_visual" type="mesh" mesh="red_tape_roll_red" material="red_tape" contype="0" conaffinity="0" group="2" />
      <geom name="red_tape_roll_white_hub_visual" type="mesh" mesh="red_tape_roll_white_hub" material="white_tape_hub" contype="0" conaffinity="0" group="2" />
      <geom name="red_tape_roll_col_00" type="box" size="0.009 0.0068 0.0215" pos="0.0475 0 0" euler="0 0 0" mass="0.05" friction="1.2 0.006 0.0001" rgba="0.95 0.02 0.015 0" group="3" />
      <geom name="red_tape_roll_col_01" type="box" size="0.009 0.0068 0.0215" pos="0.03359 0.03359 0" euler="0 0 0.785398" mass="0.05" friction="1.2 0.006 0.0001" rgba="0.95 0.02 0.015 0" group="3" />
      <geom name="red_tape_roll_col_02" type="box" size="0.009 0.0068 0.0215" pos="0 0.0475 0" euler="0 0 1.570796" mass="0.05" friction="1.2 0.006 0.0001" rgba="0.95 0.02 0.015 0" group="3" />
      <geom name="red_tape_roll_col_03" type="box" size="0.009 0.0068 0.0215" pos="-0.03359 0.03359 0" euler="0 0 2.356194" mass="0.05" friction="1.2 0.006 0.0001" rgba="0.95 0.02 0.015 0" group="3" />
      <geom name="red_tape_roll_col_04" type="box" size="0.009 0.0068 0.0215" pos="-0.0475 0 0" euler="0 0 3.141593" mass="0.05" friction="1.2 0.006 0.0001" rgba="0.95 0.02 0.015 0" group="3" />
      <geom name="red_tape_roll_col_05" type="box" size="0.009 0.0068 0.0215" pos="-0.03359 -0.03359 0" euler="0 0 3.926991" mass="0.05" friction="1.2 0.006 0.0001" rgba="0.95 0.02 0.015 0" group="3" />
      <geom name="red_tape_roll_col_06" type="box" size="0.009 0.0068 0.0215" pos="0 -0.0475 0" euler="0 0 4.712389" mass="0.05" friction="1.2 0.006 0.0001" rgba="0.95 0.02 0.015 0" group="3" />
      <geom name="red_tape_roll_col_07" type="box" size="0.009 0.0068 0.0215" pos="0.03359 -0.03359 0" euler="0 0 5.497787" mass="0.05" friction="1.2 0.006 0.0001" rgba="0.95 0.02 0.015 0" group="3" />
      <site name="red_tape_roll_site" pos="0 0 0" size="0.008" rgba="0 1 0 1" />
    </body>
    <body name="yellow_tape_roll" pos="-0.7625 0.07 0.0215">
      <freejoint name="yellow_tape_roll_joint" />
      <geom name="yellow_tape_roll_yellow_visual" type="mesh" mesh="red_tape_roll_red" material="yellow_tape" contype="0" conaffinity="0" group="2" />
      <geom name="yellow_tape_roll_white_hub_visual" type="mesh" mesh="red_tape_roll_white_hub" material="white_tape_hub" contype="0" conaffinity="0" group="2" />
      <geom name="yellow_tape_roll_col_00" type="box" size="0.009 0.0068 0.0215" pos="0.0475 0 0" euler="0 0 0" mass="0.05" friction="1.2 0.006 0.0001" rgba="0.95 0.78 0.08 0" group="3" />
      <geom name="yellow_tape_roll_col_01" type="box" size="0.009 0.0068 0.0215" pos="0.03359 0.03359 0" euler="0 0 0.785398" mass="0.05" friction="1.2 0.006 0.0001" rgba="0.95 0.78 0.08 0" group="3" />
      <geom name="yellow_tape_roll_col_02" type="box" size="0.009 0.0068 0.0215" pos="0 0.0475 0" euler="0 0 1.570796" mass="0.05" friction="1.2 0.006 0.0001" rgba="0.95 0.78 0.08 0" group="3" />
      <geom name="yellow_tape_roll_col_03" type="box" size="0.009 0.0068 0.0215" pos="-0.03359 0.03359 0" euler="0 0 2.356194" mass="0.05" friction="1.2 0.006 0.0001" rgba="0.95 0.78 0.08 0" group="3" />
      <geom name="yellow_tape_roll_col_04" type="box" size="0.009 0.0068 0.0215" pos="-0.0475 0 0" euler="0 0 3.141593" mass="0.05" friction="1.2 0.006 0.0001" rgba="0.95 0.78 0.08 0" group="3" />
      <geom name="yellow_tape_roll_col_05" type="box" size="0.009 0.0068 0.0215" pos="-0.03359 -0.03359 0" euler="0 0 3.926991" mass="0.05" friction="1.2 0.006 0.0001" rgba="0.95 0.78 0.08 0" group="3" />
      <geom name="yellow_tape_roll_col_06" type="box" size="0.009 0.0068 0.0215" pos="0 -0.0475 0" euler="0 0 4.712389" mass="0.05" friction="1.2 0.006 0.0001" rgba="0.95 0.78 0.08 0" group="3" />
      <geom name="yellow_tape_roll_col_07" type="box" size="0.009 0.0068 0.0215" pos="0.03359 -0.03359 0" euler="0 0 5.497787" mass="0.05" friction="1.2 0.006 0.0001" rgba="0.95 0.78 0.08 0" group="3" />
      <site name="yellow_tape_roll_site" pos="0 0 0" size="0.008" rgba="1 0.85 0 1" />
    </body>
    <body name="white_tape_roll" pos="-0.755 -0.165 0.0215">
      <freejoint name="white_tape_roll_joint" />
      <geom name="white_tape_roll_white_visual" type="mesh" mesh="red_tape_roll_red" material="white_tape_roll" contype="0" conaffinity="0" group="2" />
      <geom name="white_tape_roll_hub_visual" type="mesh" mesh="red_tape_roll_white_hub" material="white_tape_hub" contype="0" conaffinity="0" group="2" />
      <geom name="white_tape_roll_col_00" type="box" size="0.009 0.0068 0.0215" pos="0.0475 0 0" euler="0 0 0" mass="0.05" friction="1.2 0.006 0.0001" rgba="0.92 0.88 0.80 0" group="3" />
      <geom name="white_tape_roll_col_01" type="box" size="0.009 0.0068 0.0215" pos="0.03359 0.03359 0" euler="0 0 0.785398" mass="0.05" friction="1.2 0.006 0.0001" rgba="0.92 0.88 0.80 0" group="3" />
      <geom name="white_tape_roll_col_02" type="box" size="0.009 0.0068 0.0215" pos="0 0.0475 0" euler="0 0 1.570796" mass="0.05" friction="1.2 0.006 0.0001" rgba="0.92 0.88 0.80 0" group="3" />
      <geom name="white_tape_roll_col_03" type="box" size="0.009 0.0068 0.0215" pos="-0.03359 0.03359 0" euler="0 0 2.356194" mass="0.05" friction="1.2 0.006 0.0001" rgba="0.92 0.88 0.80 0" group="3" />
      <geom name="white_tape_roll_col_04" type="box" size="0.009 0.0068 0.0215" pos="-0.0475 0 0" euler="0 0 3.141593" mass="0.05" friction="1.2 0.006 0.0001" rgba="0.92 0.88 0.80 0" group="3" />
      <geom name="white_tape_roll_col_05" type="box" size="0.009 0.0068 0.0215" pos="-0.03359 -0.03359 0" euler="0 0 3.926991" mass="0.05" friction="1.2 0.006 0.0001" rgba="0.92 0.88 0.80 0" group="3" />
      <geom name="white_tape_roll_col_06" type="box" size="0.009 0.0068 0.0215" pos="0 -0.0475 0" euler="0 0 4.712389" mass="0.05" friction="1.2 0.006 0.0001" rgba="0.92 0.88 0.80 0" group="3" />
      <geom name="white_tape_roll_col_07" type="box" size="0.009 0.0068 0.0215" pos="0.03359 -0.03359 0" euler="0 0 5.497787" mass="0.05" friction="1.2 0.006 0.0001" rgba="0.92 0.88 0.80 0" group="3" />
      <site name="white_tape_roll_site" pos="0 0 0" size="0.008" rgba="1 1 1 1" />
    </body>
    <body name="myd_part1" pos="-0.5350 -0.263 -0.01" euler="0 1.57079632679 1.57079632679">
      <geom name="myd_part1_visual" type="mesh" mesh="myd_part1" material="myd_part_gray" contype="0" conaffinity="0" group="2" />
      <geom name="myd_part1_collision_disabled" type="mesh" mesh="myd_part1" contype="0" conaffinity="0" rgba="0 0 0 0" group="3" />
      <site name="myd_part1_site" pos="0 0 0" size="0.008" rgba="0 0.7 1 1" />
    </body>
    <body name="myd_part1_collision_proxy" pos="-0.4800 -0.1955 0">
      <geom name="myd_part1_insert_post_collision" type="cylinder" pos="0 0 0.080" size="0.025 0.080" friction="0.25 0.002 0.0001" solimp="0.95 0.99 0.001" solref="0.01 1" rgba="0.02 0.02 0.02 0.35" group="3" />
      <geom name="myd_part1_low_base_collision" type="cylinder" pos="0 0 0.004" size="0.040 0.004" friction="0.5 0.003 0.0001" solimp="0.95 0.99 0.001" solref="0.01 1" rgba="0.02 0.02 0.02 0.20" group="3" />
    </body>
    <body name="fr5_fixed_base">
      <geom name="fr5_fixed_base_geom" type="box" pos="0 0 0.01" size="0.118 0.1 0.01" material="frame_black" />
    </body>
    <body name="base_link" pos="0 0 0.02">
      <geom type="mesh" mesh="base_link" material="fr5_white" />
      <body name="shoulder_link">
        <inertial pos="5.0029e-07 -0.0040922 0.14629" quat="0.999588 0.0287044 7.54149e-06 -1.58789e-05" mass="4.3771" diaginertia="0.010731 0.0104154 0.00817191" />
        <joint name="j1" type="hinge" pos="0 0 0" axis="0 0 1" range="-3.0543 3.0543" actuatorfrcrange="-150 150" damping="10" />
        <geom type="mesh" mesh="shoulder_link" material="fr5_white" />
        <body name="upperarm_link" pos="0 0 0.152" quat="0.707105 0.707108 0 0">
          <inertial pos="-0.2125 -5.7643e-09 0.1346" quat="0.5 0.5 0.5 0.5" mass="14.458" diaginertia="0.4559 0.44974 0.028392" />
          <joint name="j2" type="hinge" pos="0 0 0" axis="0 0 1" range="-4.6251 1.4835" actuatorfrcrange="-150 150" damping="10" />
          <geom type="mesh" mesh="upperarm_link" material="fr5_white" />
          <body name="forearm_link" pos="-0.425 0 0">
            <inertial pos="-0.18793 -8.4503e-07 0.0066357" quat="0.510607 0.489172 0.489196 0.510568" mass="7.6737" diaginertia="0.16971 0.168834 0.00821541" />
            <joint name="j3" type="hinge" pos="0 0 0" axis="0 0 1" range="-2.8274 2.8274" actuatorfrcrange="-150 150" damping="10" />
            <geom type="mesh" mesh="forearm_link" material="fr5_white" />
            <body name="wrist1_link" pos="-0.39501 0 0">
              <inertial pos="4.98e-07 -0.003754 0.097155" quat="0.736149 0.676819 -6.33095e-05 7.15237e-05" mass="1.6266" diaginertia="0.00216 0.00199337 0.00154233" />
              <joint name="j4" type="hinge" pos="0 0 0" axis="0 0 1" range="-4.6251 1.4835" actuatorfrcrange="-28 28" damping="10" />
              <geom type="mesh" mesh="wrist1_link" material="fr5_white" />
              <body name="wrist2_link" pos="0 0 0.1021" quat="0.707105 0.707108 0 0">
                <inertial pos="-4.5588e-07 0.0038617 0.098257" quat="0.68712 0.726544 0.000128667 -0.000114125" mass="1.5812" diaginertia="0.0020612 0.00195889 0.00144611" />
                <joint name="j5" type="hinge" pos="0 0 0" axis="0 0 1" range="-3.0543 3.0543" actuatorfrcrange="-28 28" damping="10" />
                <geom type="mesh" mesh="wrist2_link" material="fr5_white" />
                <body name="wrist3_link" pos="0 0 0.102" quat="0.707105 -0.707108 0 0">
                  <inertial pos="0.000272898 -0.00388509 0.10695" quat="0.994194 0.107424 0.00208448 0.0058637" mass="1.2317" diaginertia="0.00236413 0.00183761 0.00147538" />
                  <joint name="j6" type="hinge" pos="0 0 0" axis="0 0 1" range="-3.0543 3.0543" actuatorfrcrange="-28 28" damping="5" />
                  <geom type="mesh" mesh="wrist3_link" material="fr5_white" />
                  <body name="robotiq_base_link" childclass="2f85" pos="0 0 0.098" euler="0 0 0">
                    <inertial mass="0.777441" pos="0 -2.70394e-05 0.0354675" quat="1 -0.00152849 0 0" diaginertia="0.000260285 0.000225381 0.000152708" />
                    <geom class="visual_gripper" pos="0 0 0.0108" quat="0 0 0 1" mesh="robotiq_base" />
                    <geom class="visual_gripper" pos="0 0 0.004" quat="0.707107 -0.707107 0 0" mesh="base_coupling" />
                    <geom class="visual_gripper" pos="0 0 0.0108" quat="1 0 0 0" mesh="c-a01-85-open" material="metal" />
                    <site name="tcp" pos="0 0 0.1489" size="0.01" />
                    <geom name="hand_capsule" class="collision_gripper" type="capsule" conaffinity="1" size="0.04 0.06" rgba="1 1 1 0.3" pos="0 0 0.01" />
                    <body name="left_driver" pos="-0.0306011 0.00475 0.0657045" quat="0.707107 -0.707107 0 0">
                      <inertial mass="0.00899563" pos="0 0.0177547 0.00107314" quat="0.681301 0.732003 0 0" diaginertia="1.72352e-06 1.60906e-06 3.22006e-07" />
                      <joint name="left_driver_joint" class="driver" />
                      <geom class="visual_gripper" pos="0.0306011 0.0549045 -0.0047" quat="0.707107 0.707107 0 0" mesh="driver" material="metal" />
                      <body name="left_coupler" pos="-0.0314249 0.00453223 -0.0102" quat="8.02038e-06 0 0 1">
                        <inertial mass="0.0140974" pos="0 0.00301209 0.0232175" quat="0.705636 -0.0455904 0.0455904 0.705636" diaginertia="4.16206e-06 3.52216e-06 8.88131e-07" />
                        <geom class="visual_gripper" pos="-0.062026 -0.0503723 0.0055" quat="0.707107 -0.707107 0 0" mesh="coupler" />
                        <geom name="left_coupler_col_1" class="pad_box2" pos="0.005 0.025 0.01" quat="1 1 -0.1 0" type="capsule" size="0.009 0.02" />
                        <geom name="left_coupler_col_2" class="pad_box2" pos="0.005 0.025 0.001" quat="1 1 -0.1 0" type="capsule" size="0.009 0.02" />
                      </body>
                    </body>
                    <body name="left_spring_link" pos="-0.0127 -0.012 0.07222" quat="0.707107 -0.707107 -4.97726e-06 -4.97726e-06">
                      <inertial mass="0.0221642" pos="-8.65005e-09 0.0181624 0.0212658" quat="0.663403 -0.244737 0.244737 0.663403" diaginertia="8.96853e-06 6.71733e-06 2.63931e-06" />
                      <joint name="left_spring_link_joint" class="spring_link" />
                      <geom class="visual_gripper" pos="0.0127 0.06142 0.01205" quat="0.707107 0.707107 0 0" type="mesh" mesh="spring_link" />
                      <body name="left_follower" pos="-0.0382079 -0.0425003 0.00295" quat="0 -1 -1.90231e-05 0">
                        <inertial mass="0.0125222" pos="0 -0.011046 0.0124786" quat="1 0.1664 0 0" diaginertia="2.67415e-06 2.4559e-06 6.02031e-07" />
                        <joint name="left_follower_joint" class="follower" />
                        <geom class="visual_gripper" pos="0.0509079 -0.10392 -0.0091" quat="0.707107 -0.707107 0 0" type="mesh" mesh="follower" />
                        <geom class="visual_gripper" pos="0.0509079 -0.10392 -0.0091" quat="0.707107 -0.707107 0 0" type="mesh" mesh="tongue" material="metal" />
                        <geom name="left_follower_pad2" class="pad_box2" type="capsule" size="0.009 0.012 0.008" pos="-0.0035 -0.002 -0.009" quat="1 1 0 0" />
                        <body name="left_pad" pos="-0.0377897 -0.103916 -0.0091" quat="0.707107 -0.707107 3.16527e-05 -3.16527e-05">
                          <geom class="pad_box2" name="left_finger_pad" />
                        </body>
                      </body>
                    </body>
                    <body name="right_driver" pos="0.0306011 -0.00475 0.0657045" quat="0 0 -0.707107 0.707107">
                      <inertial mass="0.00899563" pos="2.96931e-12 0.0177547 0.00107314" quat="0.681301 0.732003 0 0" diaginertia="1.72352e-06 1.60906e-06 3.22006e-07" />
                      <joint name="right_driver_joint" class="driver" />
                      <geom class="visual_gripper" pos="0.0306011 0.0549045 -0.0047" quat="0.707107 0.707107 0 0" mesh="driver" material="metal" />
                      <body name="right_coupler" pos="-0.0314249 0.00453223 -0.0102" quat="0 0 0 1">
                        <inertial mass="0.0140974" pos="0 0.00301209 0.0232175" quat="0.705636 -0.0455904 0.0455904 0.705636" diaginertia="4.16206e-06 3.52216e-06 8.88131e-07" />
                        <geom class="visual_gripper" pos="-0.062026 -0.0503723 0.0055" quat="0.707107 -0.707107 0 0" mesh="coupler" />
                        <geom name="right_coupler_col_1" class="pad_box2" pos="0.005 0.025 0.01" quat="1 1 -0.1 0" type="capsule" size="0.009 0.02" />
                        <geom name="right_coupler_col_2" class="pad_box2" pos="0.005 0.025 0.001" quat="1 1 -0.1 0" type="capsule" size="0.009 0.02" />
                      </body>
                    </body>
                    <body name="right_spring_link" pos="0.0127 0.012 0.07222" quat="0 0 -0.707107 0.707107">
                      <inertial mass="0.0221642" pos="-8.65005e-09 0.0181624 0.0212658" quat="0.663403 -0.244737 0.244737 0.663403" diaginertia="8.96853e-06 6.71733e-06 2.63931e-06" />
                      <joint name="right_spring_link_joint" class="spring_link" />
                      <geom class="visual_gripper" pos="0.0127 0.06142 0.01205" quat="0.707107 0.707107 0 0" mesh="spring_link" />
                      <body name="right_follower" pos="-0.0382079 -0.0425003 0.00295" quat="0 -1 1.79721e-11 0">
                        <inertial mass="0.0125222" pos="0 -0.011046 0.0124786" quat="1 0.1664 0 0" diaginertia="2.67415e-06 2.4559e-06 6.02031e-07" />
                        <joint name="right_follower_joint" class="follower" />
                        <geom class="visual_gripper" pos="0.0509079 -0.10392 -0.0091" quat="0.707107 -0.707107 0 0" mesh="tongue" material="metal" />
                        <geom class="visual_gripper" pos="0.0509079 -0.10392 -0.0091" quat="0.707107 -0.707107 0 0" mesh="follower" />
                        <geom name="right_follower_pad2" class="pad_box2" type="capsule" size="0.009 0.012 0.008" pos="-0.0035 -0.002 -0.009" quat="1 1 0 0" />
                        <body name="right_pad" pos="-0.0377897 -0.103916 -0.0091" quat="0.707107 -0.707107 3.16527e-05 -3.16527e-05">
                          <geom class="pad_box2" name="right_finger_pad" />
                        </body>
                      </body>
                    </body>
                  </body>
                </body>
              </body>
            </body>
          </body>
        </body>
      </body>
    </body>
  </worldbody>
  <contact>
    <exclude body1="robotiq_base_link" body2="left_driver" />
    <exclude body1="robotiq_base_link" body2="right_driver" />
    <exclude body1="robotiq_base_link" body2="left_spring_link" />
    <exclude body1="robotiq_base_link" body2="right_spring_link" />
    <exclude body1="right_coupler" body2="right_follower" />
    <exclude body1="left_coupler" body2="left_follower" />
  </contact>
  <equality>
    <connect anchor="-0.0179014 -0.00651468 0.0044" body1="right_follower" body2="right_coupler" solimp="0.95 0.99 0.001" solref="0.005 1" />
    <connect anchor="-0.0179014 -0.00651468 0.0044" body1="left_follower" body2="left_coupler" solimp="0.95 0.99 0.001" solref="0.005 1" />
    <joint joint1="right_driver_joint" joint2="left_driver_joint" polycoef="0 1 0 0 0" solimp="0.95 0.99 0.001" solref="0.005 1" />
  </equality>
  <actuator>
    <position name="j1_pos" joint="j1" kp="1200" kv="180" ctrlrange="-3.0543 3.0543" forcerange="-300 300" />
    <position name="j2_pos" joint="j2" kp="1800" kv="180" ctrlrange="-4.6251 1.4835" forcerange="-400 400" />
    <position name="j3_pos" joint="j3" kp="1800" kv="180" ctrlrange="-2.8274 2.8274" forcerange="-350 350" />
    <position name="j4_pos" joint="j4" kp="1800" kv="180" ctrlrange="-4.6251 1.4835" forcerange="-180 180" />
    <position name="j5_pos" joint="j5" kp="1500" kv="180" ctrlrange="-3.0543 3.0543" forcerange="-120 120" />
    <position name="j6_pos" joint="j6" kp="1500" kv="180" ctrlrange="-3.0543 3.0543" forcerange="-100 100" />
    <position name="fingers_actuator" joint="left_driver_joint" forcerange="-5 5" ctrlrange="0 0.82" kp="10" kv="1" />
  </actuator>
</mujoco>
